<?xml version="1.0" encoding="utf-8"?>
<!-- This URDF was automatically created by SolidWorks to URDF Exporter! Originally created by Stephen Brawner (brawner@gmail.com) 
     Commit Version: 1.6.0-4-g7f85cfe  Build Version: 1.6.7995.38578
     For more information, please see http://wiki.ros.org/sw_urdf_exporter -->
<robot name="robotbar_pid_flight_altitude">
  <link name="world" />

  <joint name="base_joint" type="fixed">
    <origin
      xyz="0 0 0"
      rpy="0 0 0" />
    <parent link="world" />
    <child link="base_link" />
  </joint>

  <link name="base_link">
    <inertial>
      <origin
        xyz="-3.3307E-16 0.00010179 0.56756"
        rpy="0 0 0" />
      <mass
        value="19.004" />
      <inertia
        ixx="5.2179"
        ixy="3.6943E-16"
        ixz="1.5946E-15"
        iyy="6.0568"
        iyz="-0.00036839"
        izz="1.7946" />
    </inertial>
    <visual>
      <origin
        xyz="0 0 0"
        rpy="0 0 0" />
      <geometry>
        <mesh
          filename="package://robotbar_pid_flight_altitude/meshes/base_link.STL" />
      </geometry>
      <material name="">
        <color rgba="0.79216 0.81961 0.93333 1" />
      </material>
    </visual>
    <collision>
      <origin
        xyz="0 0 0"
        rpy="0 0 0" />
      <geometry>
        <mesh
          filename="package://robotbar_pid_flight_altitude/meshes/base_link.STL" />
      </geometry>
    </collision>
  </link>

  <joint name="target_joint" type="prismatic">
    <origin
      xyz="0 -0.153 0.1095"
      rpy="0 0 0" />
    <parent
      link="base_link" />
    <child
      link="target_link" />
    <axis
      xyz="0 0 1" />
    <limit
      lower="0"
      upper="1.3"
      effort="1000"
      velocity="200" />
    <dynamics damping="0.7"/>
  </joint>

  <joint name="board_joint" type="prismatic">
    <origin
      xyz="0 0 0.108"
      rpy="0 0 0" />
    <parent
      link="base_link" />
    <child
      link="board_link" />
    <axis
      xyz="0 0 1" />
    <limit
      lower="0"
      upper="1.3"
      effort="1000"
      velocity="100" />
    <dynamics damping="0.7"/>
  </joint>

  <link name="target_link">
    <inertial>
      <origin
        xyz="6.9944E-15 -0.001587 -2.2204E-16"
        rpy="0 0 0" />
      <mass
        value="0.001035" />
      <inertia
        ixx="2.0324E-07"
        ixy="-1.749E-20"
        ixz="-4.2872E-20"
        iyy="0.0002126"
        iyz="-5.9908E-21"
        izz="0.00021276" />
    </inertial>
    <visual>
      <origin
        xyz="0 0 0"
        rpy="0 0 0" />
      <geometry>
        <mesh
          filename="package://robotbar_pid_flight_altitude/meshes/target_link.STL" />
      </geometry>
      <material
        name="">
        <color
          rgba="1 0 0 1" />
      </material>
    </visual>
    <collision>
      <origin
        xyz="0 0 0"
        rpy="0 0 0" />
      <geometry>
        <mesh
          filename="package://robotbar_pid_flight_altitude/meshes/target_link.STL" />
      </geometry>
    </collision>
  </link>

  <link name="board_link">
    <inertial>
      <origin
        xyz="-0.00053657 0 0.0050063"
        rpy="0 0 0" />
      <mass
        value="0.015701" />
      <inertia
        ixx="1.1733E-04"
        ixy="-9.2502E-19"
        ixz="-4.0352E-07"
        iyy="0.043646"
        iyz="-7.8087E-22"
        izz="0.043737" />
    </inertial>
    <visual>
      <origin
        xyz="0 0 0"
        rpy="0 0 0" />
      <geometry>
        <mesh
          filename="package://robotbar_pid_flight_altitude/meshes/board_link.STL" />
      </geometry>
      <material
        name="">
        <color
          rgba="0.79216 0.81961 0.93333 1" />
      </material>
    </visual>
    <collision>
      <origin
        xyz="0 0 0"
        rpy="0 0 0" />
      <geometry>
        <mesh
          filename="package://robotbar_pid_flight_altitude/meshes/board_link.STL" />
      </geometry>
    </collision>
  </link>

  <joint name="height_sesor_joint" type="fixed">
    <origin
      xyz="0.04 0 0.0035"
      rpy="3.1416 1.5708 3.1416" /> <!--3.1416 0 3.1416-->
    <parent
      link="board_link" />
    <child
      link="height_sensor_link" />
    <axis
      xyz="0 0 0" />
  </joint>

  <joint name="motor_joint" type="continuous">
    <origin
      xyz="0 0 0.01"
      rpy="0 0 0" />
    <parent
      link="board_link" />
    <child
      link="motor_link" />
    <axis
      xyz="0 0 -1" />
    <limit
      effort="100"
      velocity="1250" />
  </joint>

  <link name="height_sensor_link">
    <inertial>
      <origin
        xyz="7.3733E-05 -0.00024445 0.0008474"
        rpy="0 0 0" />
      <mass
        value="0.001" />
      <inertia
        ixx="2.8213E-09"
        ixy="2.4144E-12"
        ixz="3.4557E-11"
        iyy="1.0327E-08"
        iyz="3.6792E-11"
        izz="1.2859E-08" />
    </inertial>
    <visual>
      <origin
        xyz="0 0 0"
        rpy="0 -1.5708 0" />
      <geometry>
        <mesh
          filename="package://robotbar_pid_flight_altitude/meshes/height_sensor_link.STL" />
      </geometry>
      <material
        name="">
        <color
          rgba="0.79216 0.81961 0.93333 1" />
      </material>
    </visual>
    <collision>
      <origin
        xyz="0 0 0"
        rpy="0 0 0" />
      <geometry>
        <mesh
          filename="package://robotbar_pid_flight_altitude/meshes/height_sensor_link.STL" />
      </geometry>
    </collision>
  </link>

  <link name="motor_link">
    <inertial>
      <origin
        xyz="-5.3086E-07 -1.0568E-05 0.019773"
        rpy="0 0 0" />
      <mass
        value="0.065" />
      <inertia
        ixx="1.4189E-04"
        ixy="-1.4154E-04"
        ixz="-2.4139E-07"
        iyy="3.4345E-03"
        iyz="1.9009E-07"
        izz="3.4607E-03" />
    </inertial>
    <visual>
      <origin
        xyz="0 0 0"
        rpy="0 0 0" />
      <geometry>
        <mesh
          filename="package://robotbar_pid_flight_altitude/meshes/motor_link.STL" />
      </geometry>
      <material
        name="">
        <color
          rgba="0.75294 0 0 1" />
      </material>
    </visual>
    <collision>
      <origin
        xyz="0 0 0"
        rpy="0 0 0" />
      <geometry>
        <mesh
          filename="package://robotbar_pid_flight_altitude/meshes/motor_link.STL" />
      </geometry>
    </collision>
  </link>

  <gazebo reference="board_link">
    <material>Gazebo/Grey</material>
  </gazebo>

  <gazebo reference="motor_link">
    <material>Gazebo/Red</material>
  </gazebo>

  <gazebo reference="height_sensor_link">
    <material>Gazebo/Black</material>
  </gazebo>

  <!-- ROS Gazebo plugin -->
  <gazebo>
    <plugin name="gazebo_ros_control" filename="libgazebo_ros_control.so">
      <robotNamespace>/</robotNamespace>
    </plugin>
  </gazebo>

  <!-- Height sensor -->
  <gazebo reference="height_sensor_link">
    <sensor name="vl53l1xSensor" type="ray">
      <pose>0 0 0 0 0 0</pose>
      <visualize>true</visualize>
      <update_rate>10</update_rate>
      <ray>
        <scan>
          <horizontal>
            <samples>1</samples>
            <resolusion>1</resolusion>
            <min_angle>-0</min_angle>
            <max_angle>0</max_angle>
          </horizontal>
        </scan>
        <range>
          <min>0.008</min>
          <max>4</max>
          <resolusion>0.001</resolusion>
        </range>
        <noise>
          <type>gaussian</type>
          <mean>0.0</mean>
          <stddev>0.001</stddev>
        </noise>
      </ray>
      <plugin name="vl53l1x_controller" filename="libgazebo_ros_laser.so">
        <topicName>/vl53l1x_sensor/distance</topicName>
        <frameName>vl53l1x_sensor</frameName>
      </plugin>
    </sensor>
  </gazebo>

  <!-- ROS control -->
  <transmission name="target_trans">
    <type>transmission_interface/SimpleTransmission</type>
    <actuator name="target_motor" />
    <joint name="target_joint">
      <hardwareInterface>hardware_interface/PositionJointInterface</hardwareInterface>
    </joint>
  </transmission>

  <transmission name="board_trans">
    <type>transmission_interface/SimpleTransmission</type>
    <actuator name="board_motor" />
    <joint name="board_joint">
      <hardwareInterface>hardware_interface/EffortJointInterface</hardwareInterface>
    </joint>
  </transmission>

  <transmission name="motor_trans">
    <type>transmission_interface/SimpleTransmission</type>
    <actuator name="motor_motor" />
    <joint name="motor_joint">
      <hardwareInterface>hardware_interface/VelocityJointInterface</hardwareInterface>
    </joint>
  </transmission>
</robot>